Workbook

Sheet LEEME
A1: Cómo usar este archivo
B3: Este archivo es tu lista de artículos candidatos. Tienes 26 artículos para revisar.
B4: Ya está todo pegado. No tienes que pegar ni borrar nada.
A6: 1 | B6: Abre la pestaña "Candidatos". Solo verás tus filas: ya están filtradas para ti.
A7: 2 | B7: En cada fila, escribe Sigue o Sale en las columnas amarillas de la derecha, en este orden: 1. Título, 2. Resumen, 3. Cuartil, 4. Intro y conclusiones, 5. Completo.
A8: 3 | B8: Solo avanzas al siguiente filtro con las filas que dijeron Sigue. Para el cuartil escribes Q1, Q2, Q3, Q4 o No aparece.
A9: 4 | B9: La columna Resultado te dice sola cuáles quedan APROBADO.
A10: 5 | B10: Los artículos APROBADO los copias a tu otro archivo, Matriz_Joaquin.xlsx, hasta completar 12.
B12: IMPORTANTE: no toques la pestaña "Conteo" ni la pestaña "Preseleccionados". Se calculan solas.
B13: AL TERMINAR: devuélvele este archivo a Carlos, junto con Matriz_Joaquin.xlsx, tus PDF y tus capturas de Scimago.

Sheet Candidatos
A1: Trabaja solo tus filas (Asignado = Joaquín). Escribe Sigue o Sale en las columnas amarillas de la derecha.
A2: N.° | B2: Título | C2: Autores | D2: Año | E2: Revista | F2: DOI | G2: Resumen | H2: Base de origen | I2: Control | J2: Asignado | K2: 1. Título | L2: 2. Resumen | M2: 3. Cuartil | N2: 4. Intro y conclusiones | O2: 5. Completo | P2: Resultado | Q2: Afiliación (para el país) | R2: Búsqueda
A3: =IF(B3="","",ROW()-2) | B3: Machine Learning to Enhance the Detection of Terrorist Financing and Suspicious Transactions in Migrant Remittances | C3: Mbiva S.M.; Correa F.M. | D3: 2024 | E3: Journal of Risk and Financial Management | F3: 10.3390/jrfm17050181 | G3: Migrant remittances have become significant in poverty alleviation and microeconomic development in low-income countries. However, the ease of conducting global migrant remittance transfers has also introduced the risk of misuse by terrorist organizations to quickly move and conceal operational funds, facilitating terrorism financing. This study aims to develop an unsupervised machine learning algorithm capable of detecting suspicious financial transactions associated with terrorist financing in migrant remittances. To achieve this goal, a structural equation model (SEM) and an outlier detection algorithm were developed to analyze and identify suspicious transactions among the financial activities of migrants residing in Belgium. The results show that the SEM model classifies a significantly high number of transactions as suspicious, making it prone to detecting false positives. Finally, the study developed an ensemble outlier detection algorithm that comprises an isolation forest (IF) and a local outlier factor (LOF) to detect suspicious transactions in the same dataset. The model performed exceptionally well, being able to detect over 90% of suspicious transactions. © 2024 by the authors. | H3: Scopus | I3: =IF(B3="","",IF(AND(F3<>"",SUMPRODUCT(--ISNUMBER(SEARCH(Preseleccionados!$A$2:$A$11,F3)))>0),"YA ESTÁ",IF(AND(F3<>"",COUNTIF($F$3:F3,F3)>1),"REPETIDO",""))) | J3: =IF(OR(B3="",I3<>""),"",IF(MOD(COUNTIFS($B$3:B3,"<>",$I$3:I3,""),2)=1,"Carlos","Joaquín")) | P3: =IF(J3="","",IF(K3="Sale","Descartado",IF(L3="Sale","Descartado",IF(OR(M3="Q3",M3="Q4",M3="No aparece"),"Descartado",IF(N3="Sale","Descartado",IF(O3="Sigue","APROBADO","En proceso")))))) | Q3: Department of Statistics, Rhodes University, Eastern Cape, Makanda, 6139, South Africa; Department of Mathematical Statistics and Actuarial Sciences, University of the Free State, Bloemfontein, 9302, South Africa | R3: Casas de cambio
A4: =IF(B4="","",ROW()-2) | B4: A Proposed Paradigm Using Data Mining to Minimize Online Money Laundering | C4: Ouf S.; Ashraf M.; Roushdy M. | D4: 2024 | E4: Informatica (Slovenia) | F4: 10.31449/inf.v48i3.6103 | G4: Since the global financial crisis (GFC), banks have been compromised by various risks. One of the significant risks is online money laundering. It is the third-largest business in the world after currency exchange and the automotive industry. As technology has advanced, the methods of online money laundering have become more evasive. Banks' traditional methods cannot deal with online money laundering. The absence of contemporary anti-money laundering techniques has led to the rise of this criminal activity. As a result, the existing systems need effective technology to accommodate the development of online money laundering. Data mining is the technology that applies mathematical, statistical, and machine-learning techniques to extract patterns like malicious behavior of money launderers and gain information about whether the online transaction belongs to money laundering. Many research papers apply different data mining techniques to predict online money laundering. By analyzing these research papers, we found that authors focused on applying one or two data mining techniques to predict online money laundering but ignored combining many techniques like classification, clustering, and association to improve the accuracy of prediction and overcome the limitations of each of them. Therefore, this paper proposes and implements a paradigm (APPD-OML) based on classification, clustering, and association techniques to improve the accuracy of predicting and detecting online money laundering. The result of testing the proposed paradigm illustrates that the prediction and detection of online money laundering based on applying data mining techniques like classification, clustering, and association achieve a strong accuracy of 94%, f-measure of 95%, and AUC 95% which means that the proposed paradigm outperforms each technique used separately in predicting and detecting online money laundering and outperformed the other research that used data mining in this field. © 2024 Slovene Society Informatika. All rights reserved. | H4: Scopus | I4: =IF(B4="","",IF(AND(F4<>"",SUMPRODUCT(--ISNUMBER(SEARCH(Preseleccionados!$A$2:$A$11,F4)))>0),"YA ESTÁ",IF(AND(F4<>"",COUNTIF($F$3:F4,F4)>1),"REPETIDO",""))) | J4: =IF(OR(B4="",I4<>""),"",IF(MOD(COUNTIFS($B$3:B4,"<>",$I$3:I4,""),2)=1,"Carlos","Joaquín")) | K4: Sigue | L4: Sigue | N4: Sale | P4: =IF(J4="","",IF(K4="Sale","Descartado",IF(L4="Sale","Descartado",IF(OR(M4="Q3",M4="Q4",M4="No aparece"),"Descartado",IF(N4="Sale","Descartado",IF(O4="Sigue","APROBADO","En proceso")))))) | Q4: Information Systems Department, Faculty of Commerce and Business Administration, Helwan University, Helwan, Egypt; Faculty of Computers & Information Technology, Future University in Egypt New Cairo, Cairo, Egypt | R4: Casas de cambio
A5: =IF(B5="","",ROW()-2) | B5: Legal and regulatory challenges in addressing high-tech crimes in the banking sector: developing a cybersecurity risk assessment framework for Vietnam | C5: Bui L.V. | D5: 2026 | E5: Journal of Banking Regulation | F5: 10.1057/s41261-025-00302-0 | G5: High-technology crime in the banking sector has become increasingly transnational, data-intensive, and regulation-sensitive, posing challenges that extend beyond technical detection to governance, compliance, and supervisory accountability. While much of the scholarly literature emphasizes machine learning and predictive accuracy, the supervisory value of risk frameworks in emerging markets lies in their ability to remain auditable, law-anchored, and governance-ready. This paper addresses that gap by developing a comprehensive cybersecurity and financial-crime risk-assessment framework tailored to Vietnam’s banking sector. The framework explicitly maps binding regulatory instruments including cybersecurity law, anti-money laundering and counter-terrorist financing (AML/CFT) provisions, and data-governance requirements into operational control criteria with article- and section-level traceability. Risk is systematically organized across three layers: threats and exposures, control systems, and consequences, ensuring both legal coherence and operational applicability. The methodology emphasizes transparency and reproducibility, relying exclusively on public sources such as codified texts, national and cross-border statistics, sectoral incident reporting, and well-documented case studies. Validation is implemented through a three-stage protocol: (i) a Delphi panel to establish expert consensus on domain weights and cutoffs; (ii) inter-rater reliability testing using standardized scenarios to measure scoring consistency; and (iii) sensitivity and stress testing to probe the robustness of results under perturbations of legal salience and corridor exposure. Supplementary case-based scoring of public incidents provides applied demonstrations, reinforcing the framework’s capacity to generate governance-grade insights without reliance on proprietary transaction data. The findings yield a supervision-grade instrument that makes error-cost asymmetries explicit, particularly the higher regulatory cost of false negatives (FN) compared to false positives (FP) in AML/CFT contexts while operationalizing statutory obligations for data localization, third-country transfers, and suspicious transaction reporting. By embedding corridor-specific oversight, explainability artifacts for reviewer workflows, and proportionality mechanisms anchored in public corridor intelligence, the framework equips both banks and regulators with a deployable tool for prioritizing remediation, harmonizing oversight documentation, and preparing for in-country validation within regulatory sandboxes. More broadly, it demonstrates a replicable pathway for emerging markets to align supervisory technology with global standards while preserving transparency, auditability, and contextual sensitivity. © The Author(s) 2026. | H5: Scopus | I5: =IF(B5="","",IF(AND(F5<>"",SUMPRODUCT(--ISNUMBER(SEARCH(Preseleccionados!$A$2:$A$11,F5)))>0),"YA ESTÁ",IF(AND(F5<>"",COUNTIF($F$3:F5,F5)>1),"REPETIDO",""))) | J5: =IF(OR(B5="",I5<>""),"",IF(MOD(COUNTIFS($B$3:B5,"<>",$I$3:I5,""),2)=1,"Carlos","Joaquín")) | P5: =IF(J5="","",IF(K5="Sale","Descartado",IF(L5="Sale","Descartado",IF(OR(M5="Q3",M5="Q4",M5="No aparece"),"Descartado",IF(N5="Sale","Descartado",IF(O5="Sigue","APROBADO","En proceso")))))) | Q5: Bristol Law School, University of the West of England, Bristol, United Kingdom; International School, Vietnam National University, Hanoi, Viet Nam | R5: Bancos
A6: =IF(B6="","",ROW()-2) | B6: The Imbalanced Classification of Fraudulent Bank Transactions Using Machine Learning | C6: Ruchay A.; Feldman E.; Cherbadzhi D.; Sokolov A. | D6: 2023 | E6: Mathematics | F6: 10.3390/math11132862 | G6: This article studies the development of a reliable AI model to detect fraudulent bank transactions, including money laundering, and illegal activities with goods and services. The proposed machine learning model uses the CreditCardFraud dataset and utilizes multiple algorithms with different parameters. The results are evaluated using Accuracy, Precision, Recall, F1 score, and IBA. We have increased the reliability of the imbalanced classification of fraudulent credit card transactions in comparison to the best known results by using the Tomek links resampling algorithm of the imbalanced CreditCardFraud dataset. The reliability of the results, using the proposed model based on the TPOT and RandomForest algorithms, has been confirmed by using 10-fold cross-validation. It is shown that on the dataset the accuracy of the proposed model detecting fraudulent bank transactions reaches 99.99%. © 2023 by the authors. | H6: Scopus | I6: =IF(B6="","",IF(AND(F6<>"",SUMPRODUCT(--ISNUMBER(SEARCH(Preseleccionados!$A$2:$A$11,F6)))>0),"YA ESTÁ",IF(AND(F6<>"",COUNTIF($F$3:F6,F6)>1),"REPETIDO",""))) | J6: =IF(OR(B6="",I6<>""),"",IF(MOD(COUNTIFS($B$3:B6,"<>",$I$3:I6,""),2)=1,"Carlos","Joaquín")) | K6: Sigue | L6: Sigue | N6: Sale | P6: =IF(J6="","",IF(K6="Sale","Descartado",IF(L6="Sale","Descartado",IF(OR(M6="Q3",M6="Q4",M6="No aparece"),"Descartado",IF(N6="Sale","Descartado",IF(O6="Sigue","APROBADO","En proceso")))))) | Q6: Department of Information Security, South Ural State University (National Research University), Chelyabinsk, 454080, Russian Federation; Department of Mathematics, Chelyabinsk State University, Chelyabinsk, 454001, Russian Federation | R6: Bancos
A7: =IF(B7="","",ROW()-2) | B7: Explainable deep learning model for predicting money laundering transactions | C7: Kute D.V.; Pradhan B.; Shukla N.; Alamri A. | D7: 2024 | E7: International Journal on Smart Sensing and Intelligent Systems | F7: 10.2478/ijssis-2024-0027 | G7: Money laundering has been a global issue for decades. The ever-changing technology landscape, digital channels, and regulations make it increasingly difficult. Financial institutions use rule-based systems to detect suspicious money laundering transactions. However, it suffers from large false positives (FPs) that lead to operational efforts or misses on true positives (TPs) that increase the compliance risk. This paper presents a study of convolutional neural network (CNN) to predict money laundering and employs SHapley Additive exPlanations (SHAP) explainable artificial intelligence (AI) method to explain the CNN predictions. The results highlight the role of CNN in detecting suspicious transactions with high accuracy and SHAP’s role in bringing out the rationale of deep learning predictions. © 2024 Kute et al. | H7: Scopus | I7: =IF(B7="","",IF(AND(F7<>"",SUMPRODUCT(--ISNUMBER(SEARCH(Preseleccionados!$A$2:$A$11,F7)))>0),"YA ESTÁ",IF(AND(F7<>"",COUNTIF($F$3:F7,F7)>1),"REPETIDO",""))) | J7: =IF(OR(B7="",I7<>""),"",IF(MOD(COUNTIFS($B$3:B7,"<>",$I$3:I7,""),2)=1,"Carlos","Joaquín")) | P7: =IF(J7="","",IF(K7="Sale","Descartado",IF(L7="Sale","Descartado",IF(OR(M7="Q3",M7="Q4",M7="No aparece"),"Descartado",IF(N7="Sale","Descartado",IF(O7="Sigue","APROBADO","En proceso")))))) | Q7: Centre for Advanced Modelling and Geospatial Information Systems (CAMGIS), Faculty of Engineering and Information Technology, University of Technology Sydney, Sydney, 2007, NSW, Australia; Department of Business Strategy and Innovation, Griffith Business School, Griffith University, Brisbane, 4111, QLD, Australia; Department of Geology and Geophysics, College of Science, King Saud University, Riyadh, 11451, Saudi Arabia | R7: Bancos
A8: =IF(B8="","",ROW()-2) | B8: Anti-money laundering powered by graph machine learning: 'Show me your friends and I will tell you who you are' | C8: Astrova I. | D8: 2023 | E8: Intelligent Decision Technologies | F8: 10.3233/IDT-220193 | G8: Today financial institutions have been investing billions of US dollars to detect money laundering. When financial institutions are found to have their customers conduct money laundering through them, they are subjected to large penalties. Moreover, their reputation suffers greatly through public exposure. In response, financial institutions have been exploring opportunities to use graph machine learning algorithms. This paper describes one of those algorithms called Anti-TrustRank and demonstrates how it can be used to identify money launderers. In contrast to many other algorithms, Anti-TrustRank calls for selecting a very small set of customers to be confirmed by human experts (e.g., compliance officers or analysts) as money launderers. Once this set has been identified, Anti-TrustRank seeks out customers linked (either directly or indirectly) to those money launderers. © 2023 - IOS Press. All rights reserved. | H8: Scopus | I8: =IF(B8="","",IF(AND(F8<>"",SUMPRODUCT(--ISNUMBER(SEARCH(Preseleccionados!$A$2:$A$11,F8)))>0),"YA ESTÁ",IF(AND(F8<>"",COUNTIF($F$3:F8,F8)>1),"REPETIDO",""))) | J8: =IF(OR(B8="",I8<>""),"",IF(MOD(COUNTIFS($B$3:B8,"<>",$I$3:I8,""),2)=1,"Carlos","Joaquín")) | K8: Sigue | L8: Sigue | P8: =IF(J8="","",IF(K8="Sale","Descartado",IF(L8="Sale","Descartado",IF(OR(M8="Q3",M8="Q4",M8="No aparece"),"Descartado",IF(N8="Sale","Descartado",IF(O8="Sigue","APROBADO","En proceso")))))) | Q8: Applied Artificial Intelligence Group, Department of Software Science, Tallinn University of Technology, Akadeemia tee 21, Tallinn, 12618, Estonia | R8: Bancos
A9: =IF(B9="","",ROW()-2) | B9: AI culture ‘profiling’ and anti-money laundering: Efficacy vs ethics | C9: Goodell J.W.; Muckley C.B.; Neelakantan P.; Ryan D.; Yu P.-S. | D9: 2025 | E9: International Review of Financial Analysis | F9: 10.1016/j.irfa.2025.103980 | G9: Using extensive transaction and money laundering detection data, at a globally important financial institution, we investigate the efficacy of including facets of national culture in formulating anti-money laundering predictions. For corporate and individual accounts, Hofstede individualism scores of the country in which a customer is resident, or from which a wire is sent/received, are of first-order importance in the detection of money laundering. When combined with account and transaction data; as well as even a proprietary institutional algorithm, individualism scores continue to determine the models’ predictive performances. The efficacy of cultural profiling in money laundering detection underscores the need for stringent and enforced data protection to prohibit its use. This will safeguard the civil right of individuals to privacy and promote financial inclusion. © 2025 Elsevier Inc. | H9: Scopus | I9: =IF(B9="","",IF(AND(F9<>"",SUMPRODUCT(--ISNUMBER(SEARCH(Preseleccionados!$A$2:$A$11,F9)))>0),"YA ESTÁ",IF(AND(F9<>"",COUNTIF($F$3:F9,F9)>1),"REPETIDO",""))) | J9: =IF(OR(B9="",I9<>""),"",IF(MOD(COUNTIFS($B$3:B9,"<>",$I$3:I9,""),2)=1,"Carlos","Joaquín")) | P9: =IF(J9="","",IF(K9="Sale","Descartado",IF(L9="Sale","Descartado",IF(OR(M9="Q3",M9="Q4",M9="No aparece"),"Descartado",IF(N9="Sale","Descartado",IF(O9="Sigue","APROBADO","En proceso")))))) | Q9: The University of Akron, Akron, OH, United States; Smurfit Graduate School of Business and Geary Institute, University College Dublin, Ireland; Indian Institute of Technology Kanpur, India; NCLA, Physics, School of Natural Sciences, University of Galway, Ireland | R9: Bancos
A10: =IF(B10="","",ROW()-2) | B10: Predicting money laundering sanctions using machine learning algorithms and artificial neural networks | C10: Lokanan M.E. | D10: 2024 | E10: Applied Economics Letters | F10: 10.1080/13504851.2023.2176435 | G10: This article used machine learning (ML) and artificial neural network (ANN) algorithms to predict the likelihood of a country being sanctioned by the Basel Institute on Governance for not adhering to anti-money laundering (AML) standards. Data for this paper came from the Basel AML Index and the World Bank. The results showed that the logistic regression and support vector machine (SVM) classifiers had the highest performance and balanced accuracy scores in sanction prediction. Additionally, these two algorithms also had the highest precision, specificity, and F1 scores, indicating that they were robust in their predictions of money laundering sanctions. In contrast to the ML classifiers, the ANN model had the highest sensitivity and receiver operating characteristic scores for money laundering sanctions. The strongest predictors of sanctions are financial transparency, political and legal risks, unemployment rate, and money laundering and terrorist financing risks. These findings reinforce the potential practical applications of ML and ANN models in predicting sanctions. © 2023 Informa UK Limited, trading as Taylor & Francis Group. | H10: Scopus | I10: =IF(B10="","",IF(AND(F10<>"",SUMPRODUCT(--ISNUMBER(SEARCH(Preseleccionados!$A$2:$A$11,F10)))>0),"YA ESTÁ",IF(AND(F10<>"",COUNTIF($F$3:F10,F10)>1),"REPETIDO",""))) | J10: =IF(OR(B10="",I10<>""),"",IF(MOD(COUNTIFS($B$3:B10,"<>",$I$3:I10,""),2)=1,"Carlos","Joaquín")) | K10: Sigue | L10: Sale | P10: =IF(J10="","",IF(K10="Sale","Descartado",IF(L10="Sale","Descartado",IF(OR(M10="Q3",M10="Q4",M10="No aparece"),"Descartado",IF(N10="Sale","Descartado",IF(O10="Sigue","APROBADO","En proceso")))))) | Q10: Faculty of Management, Royal Roads University, Victoria, BC, Canada | R10: Bancos
A11: =IF(B11="","",ROW()-2) | B11: Optimization of Deep Learning-Based Model for Identification of Credit Card Frauds | C11: Palivela H.; Rishiwal V.; Bhushan S.; Alotaibi A.; Agarwal U.; Kumar P.; Yadav M. | D11: 2024 | E11: IEEE Access | F11: 10.1109/ACCESS.2024.3440637 | G11: With the growth of the internet, the landscape of commercial transactions has undergone significant changes. The digital revolution has permeated various aspects of our daily lives, notably transforming the financial system through digital money transfers across global distances. Digital transactions, including online purchases, money transfers, banking, and investing, have become routine. This shift has provided many advantages and opened the door for illegal activities such as money laundering. This research aims to identify transaction patterns to help algorithms recognize and flag scammers. We propose a deep learning-based sequential model framework to optimize fraud and non-fraud transaction classification. Proposed approach incorporates methods of ensemble learning including Gradient Boost, Random Forest, Logistic Regression, and Voting Classifiers, along with hyperparameter tuning to prevent overfitting. To solve the dataset inconsistency common in credit card dataset, we used techniques like under-sampling and the Synthetic Minority Over-sampling Technique (SMOTE) with specific machine learning (ML) algorithms. Our methodology involves data pre-processing, feature engineering, model selection, and evaluation. We leveraged the computational power of Google Colab for efficient model training and testing. Temporal features were extracted to capture transaction patterns over time, such as frequency and timing, along with features based on transaction amounts, merchant types, and geographic locations to detect subtle anomalies indicative of fraud. These features were input into a supervised learning algorithm, resulting in a model significantly outperforming baseline methods. The model was tested using a sizable dataset of anonymized transactions made with credit cards, and its effectiveness was measured using metrics such as accuracy, precision, recall, and F1-score. While it cannot entirely prevent fraudulent transactions, it effectively manages false positives through careful review, achieving an accuracy of 99.59%, surpassing other innovative models. © 2013 IEEE. | H11: Scopus | I11: =IF(B11="","",IF(AND(F11<>"",SUMPRODUCT(--ISNUMBER(SEARCH(Preseleccionados!$A$2:$A$11,F11)))>0),"YA ESTÁ",IF(AND(F11<>"",COUNTIF($F$3:F11,F11)>1),"REPETIDO",""))) | J11: =IF(OR(B11="",I11<>""),"",IF(MOD(COUNTIFS($B$3:B11,"<>",$I$3:I11,""),2)=1,"Carlos","Joaquín")) | P11: =IF(J11="","",IF(K11="Sale","Descartado",IF(L11="Sale","Descartado",IF(OR(M11="Q3",M11="Q4",M11="No aparece"),"Descartado",IF(N11="Sale","Descartado",IF(O11="Sigue","APROBADO","En proceso")))))) | Q11: Damac Properties, LLC, Dubai, United Arab Emirates; M.J.P. Rohilkhand University, Department of CSIT, Bareilly, 243006, India; Universiti Teknologi PETRONAS, Department of CIS, Perak, Seri Iskandar, 32160, Malaysia; Taif University, College of Computers and Information Technology, Department of Computer Science, Taif, 26571, Saudi Arabia; RBMI Group of Institutions, Department of CSIT, Bareilly, 224001, India; Swami Rama Himalayan University, Department of Computer Science and Engineering, Dehradun, 248016, India; Bareilly College, Department of Computer Science, Bareilly, 243001, India | R11: Bancos
A12: =IF(B12="","",ROW()-2) | B12: The importance of governance in artificial intelligence and machine learning technology | C12: Chieng S.; Dasgupta S. | D12: 2025 | E12: Journal of Financial Compliance | F12: 10.69554/PKAQ4460 | G12: Financial institutions increasingly deploy artificial intelligence (AI) and machine learning (ML) solutions to enhance compliance processes. While this trend promises significant efficiency gains, it also introduces complex governance challenges that compliance executives must effectively address. Drawing on regulatory developments, technical considerations and industry best practices, this paper presents the process to develop a comprehensive governance framework for mitigating risks associated with AI/ ML implementation in compliance functions. This paper concludes with a forward-looking perspective on evolving governance requirements as AI/ML technologies continue to transform financial compliance. This article is also included in The Business & Management Collection which can be accessed at https://hstalks.com/business/. © Henry Stewart Publications. | H12: Scopus | I12: =IF(B12="","",IF(AND(F12<>"",SUMPRODUCT(--ISNUMBER(SEARCH(Preseleccionados!$A$2:$A$11,F12)))>0),"YA ESTÁ",IF(AND(F12<>"",COUNTIF($F$3:F12,F12)>1),"REPETIDO",""))) | J12: =IF(OR(B12="",I12<>""),"",IF(MOD(COUNTIFS($B$3:B12,"<>",$I$3:I12,""),2)=1,"Carlos","Joaquín")) | K12: Sale | P12: =IF(J12="","",IF(K12="Sale","Descartado",IF(L12="Sale","Descartado",IF(OR(M12="Q3",M12="Q4",M12="No aparece"),"Descartado",IF(N12="Sale","Descartado",IF(O12="Sigue","APROBADO","En proceso")))))) | Q12: Interactive Brokers, One Pickwick Plaza, Greenwich, 06830, CT, United States | R12: Bancos
A13: =IF(B13="","",ROW()-2) | B13: Comparative analysis of machine learning algorithms for money laundering detection | C13: Ajagbe S.A.; Majola S.; Mudali P. | D13: 2025 | E13: Discover Artificial Intelligence | F13: 10.1007/s44163-025-00397-4 | G13: This study explored the effectiveness of anomaly detection techniques in identifying fraudulent financial transactions, with a particular focus on money laundering activities. The research addressed the growing challenges of financial fraud, which significantly impacts economies and financial institutions by leading to substantial monetary losses and undermining trust in financial systems. This research examined contemporary machine learning (ML) algorithms, including XGBoost, K-Nearest Neighbors, Random Forest, Isolation Forest, and Support Vector Machines, to analyze transaction data for anomalies indicative of fraudulent behavior. This study’s approach involves data collecting, system design, implementation, data analysis, and experimental setup. This research aimed to identify robust algorithms for detecting financial fraud. In the results notably, XGBoost shows an output of 1.0, 1.0, 1.0, 1.0, and 0.94 for accuracy, precision, recall, F1 score and AUC respectively to outperform other ML algorithms experimented in money laundering detection. The findings underscore the potential of ML algorithms capability to combat money laundering and indeed enhance anti-money efforts and offer financial institutions a powerful, resource-efficient method for fraud detection in large-scale transaction environments. © The Author(s) 2025. | H13: Scopus | I13: =IF(B13="","",IF(AND(F13<>"",SUMPRODUCT(--ISNUMBER(SEARCH(Preseleccionados!$A$2:$A$11,F13)))>0),"YA ESTÁ",IF(AND(F13<>"",COUNTIF($F$3:F13,F13)>1),"REPETIDO",""))) | J13: =IF(OR(B13="",I13<>""),"",IF(MOD(COUNTIFS($B$3:B13,"<>",$I$3:I13,""),2)=1,"Carlos","Joaquín")) | P13: =IF(J13="","",IF(K13="Sale","Descartado",IF(L13="Sale","Descartado",IF(OR(M13="Q3",M13="Q4",M13="No aparece"),"Descartado",IF(N13="Sale","Descartado",IF(O13="Sigue","APROBADO","En proceso")))))) | Q13: Department of Computer Science, University of Zululand, KZN, Kwadlangezwa, 3886, South Africa; Department of Computer Engineering, Abiola Ajimobi Technical University, Ibadan, 200255, Nigeria | R13: Bancos
A14: =IF(B14="","",ROW()-2) | B14: Scalable Community-Enriched Graph Representation Learning for Group-Level Anomaly Detection in Financial Transactions | C14: Nourollah Z.; Rezvani M.; Zahedi M. | D14: 2027 | E14: International Journal of Engineering, Transactions A: Basics | F14: 10.5829/ije.2027.40.03c.10 | G14: Identifying suspicious subnetworks in financial transaction systems is crucial for preventing fraud and mitigating institutional risks. However, detecting organized illicit activities remains challenging because of evolving network structures and sophisticated concealment strategies that intentionally obscure connectivity to bypass topology-driven detection. This study presents FinCEG-Net, a scalable framework for group-level anomaly detection. It comprises three stages: (1) Transaction Graph Construction, modeling monetary flows as a directed attributed graph; (2) Community-Enriched Graph Representation Learning, where graph representation learning is employed to estimate semantic edge affinities that guide community structuring. This process enables the discovery of latent illicit structures, which are groups that are topologically sparse yet behaviorally cohesive, thereby mitigating structural bias in density-driven clustering. The representation is further enriched through an Institution-Enriched Group Graph (IEGG), which integrates interbank relationships to enhance cross-institution information propagation. (3) Suspicious Subnetwork Detection, where a supervised classifier fuses multimodal representations to identify high-risk transaction groups in batch and near-real-time settings. Experiments on real-world datasets from an Iranian bank and Romania's Libra Internet Bank demonstrated that FinCEG-Net consistently outperformed the baseline models, achieving substantial improvements in PRAUC, precision, recall, and F1-score. These results highlight the effectiveness of the proposed framework in identifying suspicious transaction groups in the real world. © 2027 The author(s). This is an open access article distributed under the terms of the Creative Commons Attribution (CC BY 4.0), which permits unrestricted use, distribution, and reproduction in any medium, as long as the original authors and source are cited. No permission is required from the authors or the publishers. | H14: Scopus | I14: =IF(B14="","",IF(AND(F14<>"",SUMPRODUCT(--ISNUMBER(SEARCH(Preseleccionados!$A$2:$A$11,F14)))>0),"YA ESTÁ",IF(AND(F14<>"",COUNTIF($F$3:F14,F14)>1),"REPETIDO",""))) | J14: =IF(OR(B14="",I14<>""),"",IF(MOD(COUNTIFS($B$3:B14,"<>",$I$3:I14,""),2)=1,"Carlos","Joaquín")) | P14: =IF(J14="","",IF(K14="Sale","Descartado",IF(L14="Sale","Descartado",IF(OR(M14="Q3",M14="Q4",M14="No aparece"),"Descartado",IF(N14="Sale","Descartado",IF(O14="Sigue","APROBADO","En proceso")))))) | Q14: Faculty of Computer Engineering, Shahrood University of Technology, Shahrood, Iran | R14: Bancos
A15: =IF(B15="","",ROW()-2) | B15: Hybrid deep learning for anti-money laundering: Unsupervised detection of emerging schemes via feature fusion and explainable artificial intelligence | C15: Kungu C.O.; Senagi K.; Omondi E. | D15: 2026 | E15: Machine Learning with Applications | F15: 10.1016/j.mlwa.2026.100856 | G15: Traditional rule-based anti-money laundering (AML) transaction monitoring systems suffer from high false-positive rates and rigidity in detecting complex emerging risk. This limitation has prompted changes to the Financial Action Task Force (FATF) recommendation 16, mandating the use of advanced systems for detecting money laundering schemes in cross-border payments. This study developed a hybrid framework integrating VAE-learned behavioural latent factors, GNN-captured relational network signals, and rule-based heuristics for enhanced anomaly detection. The model was evaluated on 54,258 real-world cross-border transaction records from an East African commercial bank. The One-Class SVM, optimised via a rigorous grid search proved superior compared to Isolation Forest and Local Outlier Factor benchmark, achieving a precision of 99.63% in the top 5% of prioritised alerts. Independent validation by a Kenyan financial institution confirms a batch processing speed of 1000 transactions per second on standard computer hardware (Intel Core i7, 16 GB RAM) and efficient high-priority alert triage, key requirements for deployment in financial institutions. Shapley additive explanations analysis further provided the interpretability of the feature contribution to the model performance. These results demonstrated that integration of rule-based features with deep-learning embeddings improves compliance work efficiency and proven pathway for resource-constrained financial institutions to comply with FATF regulatory demands upcoming in 2030. © 2026 The Authors. | H15: Scopus | I15: =IF(B15="","",IF(AND(F15<>"",SUMPRODUCT(--ISNUMBER(SEARCH(Preseleccionados!$A$2:$A$11,F15)))>0),"YA ESTÁ",IF(AND(F15<>"",COUNTIF($F$3:F15,F15)>1),"REPETIDO",""))) | J15: =IF(OR(B15="",I15<>""),"",IF(MOD(COUNTIFS($B$3:B15,"<>",$I$3:I15,""),2)=1,"Carlos","Joaquín")) | K15: Sale | P15: =IF(J15="","",IF(K15="Sale","Descartado",IF(L15="Sale","Descartado",IF(OR(M15="Q3",M15="Q4",M15="No aparece"),"Descartado",IF(N15="Sale","Descartado",IF(O15="Sigue","APROBADO","En proceso")))))) | Q15: Institute of Mathematical Sciences, Strathmore University, P.O. Box 59857-00200, Nairobi, Kenya; @ilabAfrica, Strathmore University, P.O. Box 59857-00200, Nairobi, Kenya; International Centre of Insect Physiology and Ecology, Duduville Campus, off Thika Road, Kasarani, P.O. Box 30772-00100, Nairobi, Kenya; African Population and Health Research Center, P.O. Box 10787-00100, Nairobi, Kenya | R15: Bancos
A16: =IF(B16="","",ROW()-2) | B16: Developing a scoring model for managing money laundering transactions using machine learning | C16: Halford E.; Gibson I.; Newfield M.; Dhanwala M. | D16: 2025 | E16: Journal of Money Laundering Control | F16: 10.1108/JMLC-09-2024-0152 | G16: Purpose: The purpose of this study is twofold. Firstly, this study outlines the creation of an ML “bolt on” transaction monitoring risk scoring model. This ML model uses predictive classification to score the likelihood of an alert being a false or true positive based on historical data. Secondly, this study explores the results of implementing the model in a real-world environment. This is valuable, as it explores the potential to reduce the workload on human analysts responsible for reviewing alerts, by “hibernating” low-risk alerts and “auto-escalating” high-risk alerts. Design/methodology/approach: Machine learning is used to create a “bolt on” model that sits on top of existing rule-based transaction monitoring systems to improve their effectiveness and efficiency. This was achieved by developing a model to mimic the analysts alert review process with the aim of improving efficiency, reducing investigation timeliness and ultimately reducing time-to-SAR duration. The model did so by scoring anti-money laundering (AML) alerts to help conduct three actions: automatic hibernation of low-risk alerts; review of medium-risk alerts by the level 1 team; and auto-escalation of high-risk alerts to the level 2 team for detailed investigation. Findings: The model was successful in consistently identifying low-risk alerts correctly, significantly reducing the volume of false positives that needed manual review. Prior to implementation, 100% of alerts had to be reviewed, by the end of the examined period, 19% of alerts were hibernated and 18% of alerts were auto-escalated. Time taken to investigate and submit SARs was reduced by 61%. Practical implications: The practical implications of the study lie in its contributions to helping banking institutions effectively keep pace with the increasing volume of transactions, in a cost effective and efficient manner, which has a positive effect on their reputation through enhancing their AML response. Social implications: The model outlined greatly enhances the timeliness of investigations, which is crucial for money laundering prevention and enables timely responses by institutions and law enforcement agencies to make better use of the investigation timeframe after an offence is identified, enabling them to more rapidly address threats, freeze assets when necessary, and secure vital evidence before it is lost. Originality/value: This study provides a blueprint for other financial institutions to consider similar approaches to AML. This is significant because previous studies of machine learning applications in the domain of AML have not explored this type of use before, particularly in the context of machine learning ensembled techniques. It also addressed several cited limitations of previous research by increasing the depth of information in the datasets used and providing a formal evaluation. Importantly, the blueprint and evaluation metrics used in this study ensure its reproducibility, addressing another previously identified academic issue. © 2025, Eric Halford, Ian Gibson, Mark Newfield and Mufazzal Dhanwala. | H16: Scopus | I16: =IF(B16="","",IF(AND(F16<>"",SUMPRODUCT(--ISNUMBER(SEARCH(Preseleccionados!$A$2:$A$11,F16)))>0),"YA ESTÁ",IF(AND(F16<>"",COUNTIF($F$3:F16,F16)>1),"REPETIDO",""))) | J16: =IF(OR(B16="",I16<>""),"",IF(MOD(COUNTIFS($B$3:B16,"<>",$I$3:I16,""),2)=1,"Carlos","Joaquín")) | P16: =IF(J16="","",IF(K16="Sale","Descartado",IF(L16="Sale","Descartado",IF(OR(M16="Q3",M16="Q4",M16="No aparece"),"Descartado",IF(N16="Sale","Descartado",IF(O16="Sigue","APROBADO","En proceso")))))) | Q16: Department of Research and Innovation, Rabdan Academy, Abu Dhabi, United Arab Emirates | R16: Bancos
A17: =IF(B17="","",ROW()-2) | B17: Leveraging artificial intelligence for enhanced anti-money laundering in financial institutions | C17: Premkumar A.; Vidyavathi K.; Sowmya V.L.; Alfurhood B.S.; Irudayasamy A.; Natarajan R. | D17: 2026 | E17: Discover Computing | F17: 10.1007/s10791-026-10142-9 | G17: Financial institutions continue to face a significant challenge with money laundering and need intelligent, scalable ways to detect illegal financial activity. This paper introduces a machine learning-driven platform for detecting suspicious financial activities in transactional data with a fixed schema, enriched with temporal, behavioral, and financial profile features. Extensive experiments were performed with several popular supervised learning algorithms, including Logistic regression, Decision tree, Random Forest, Gradient Boosting, AdaBoost, K-Nearest Neighbour (KNN), Support vector machine, and Naïve Bayes. The Gradient Boosting classifier performed best overall, achieving an Accuracy of 90.59%, a precision of 90.61%, a recall of 90.59%, and an F1-score of 90.60 in balanced detection, with the highest reliability for detecting suspicious financial transactions. It showed better generalization and robust classification performance than the other models, especially in real anti-money laundering problems, where it performed excellently. These results demonstrate that recent artificial intelligence could fortify anti-money laundering systems by automating and improving the detection of high-risk financial activity. The framework provides a scalable and feasible approach to ensure compliance, manage risk, and secure finances for larger organizations. © The Author(s) 2026. | H17: Scopus | I17: =IF(B17="","",IF(AND(F17<>"",SUMPRODUCT(--ISNUMBER(SEARCH(Preseleccionados!$A$2:$A$11,F17)))>0),"YA ESTÁ",IF(AND(F17<>"",COUNTIF($F$3:F17,F17)>1),"REPETIDO",""))) | J17: =IF(OR(B17="",I17<>""),"",IF(MOD(COUNTIFS($B$3:B17,"<>",$I$3:I17,""),2)=1,"Carlos","Joaquín")) | P17: =IF(J17="","",IF(K17="Sale","Descartado",IF(L17="Sale","Descartado",IF(OR(M17="Q3",M17="Q4",M17="No aparece"),"Descartado",IF(N17="Sale","Descartado",IF(O17="Sigue","APROBADO","En proceso")))))) | Q17: Manipal Institute of Technology Bengaluru, Manipal Academy of Higher Education, Manipal, India; Electronics and Communication Engineering Department, Selvam College of Technology, Salem Road (NH44), Pappinaickenpatti (post), Tamil Nadu, Namakkal, 637003, India; Department of Artificial Intelligence and Machine Learning, BMS Institute of Technology & Management, Bengaluru, 560119, India; Department of Computer Sciences, College of Computer and Information Sciences, Princess Nourah bint Abdulrahman University, P.O. Box 84428, Riyadh, 11671, Saudi Arabia; Department of Computing and Information Sciences, College of Computing and Information Sciences, University of Technology and Applied Sciences, Nizwa, 611, Oman; Department of Computing and Information Sciences, College of Computing and Information Sciences, University of Technology and Applied Sciences, AI-Aqr, Shinas, 324, Oman | R17: Bancos
A18: =IF(B18="","",ROW()-2) | B18: A Proposed Paradigm Using Data Mining to Minimize Online Money Laundering | C18: Ouf S.; Ashraf M.; Roushdy M. | D18: 2024 | E18: Informatica (Slovenia) | F18: 10.31449/inf.v48i3.6103 | G18: Since the global financial crisis (GFC), banks have been compromised by various risks. One of the significant risks is online money laundering. It is the third-largest business in the world after currency exchange and the automotive industry. As technology has advanced, the methods of online money laundering have become more evasive. Banks' traditional methods cannot deal with online money laundering. The absence of contemporary anti-money laundering techniques has led to the rise of this criminal activity. As a result, the existing systems need effective technology to accommodate the development of online money laundering. Data mining is the technology that applies mathematical, statistical, and machine-learning techniques to extract patterns like malicious behavior of money launderers and gain information about whether the online transaction belongs to money laundering. Many research papers apply different data mining techniques to predict online money laundering. By analyzing these research papers, we found that authors focused on applying one or two data mining techniques to predict online money laundering but ignored combining many techniques like classification, clustering, and association to improve the accuracy of prediction and overcome the limitations of each of them. Therefore, this paper proposes and implements a paradigm (APPD-OML) based on classification, clustering, and association techniques to improve the accuracy of predicting and detecting online money laundering. The result of testing the proposed paradigm illustrates that the prediction and detection of online money laundering based on applying data mining techniques like classification, clustering, and association achieve a strong accuracy of 94%, f-measure of 95%, and AUC 95% which means that the proposed paradigm outperforms each technique used separately in predicting and detecting online money laundering and outperformed the other research that used data mining in this field. © 2024 Slovene Society Informatika. All rights reserved. | H18: Scopus | I18: =IF(B18="","",IF(AND(F18<>"",SUMPRODUCT(--ISNUMBER(SEARCH(Preseleccionados!$A$2:$A$11,F18)))>0),"YA ESTÁ",IF(AND(F18<>"",COUNTIF($F$3:F18,F18)>1),"REPETIDO",""))) | J18: =IF(OR(B18="",I18<>""),"",IF(MOD(COUNTIFS($B$3:B18,"<>",$I$3:I18,""),2)=1,"Carlos","Joaquín")) | P18: =IF(J18="","",IF(K18="Sale","Descartado",IF(L18="Sale","Descartado",IF(OR(M18="Q3",M18="Q4",M18="No aparece"),"Descartado",IF(N18="Sale","Descartado",IF(O18="Sigue","APROBADO","En proceso")))))) | Q18: Information Systems Department, Faculty of Commerce and Business Administration, Helwan University, Helwan, Egypt; Faculty of Computers & Information Technology, Future University in Egypt New Cairo, Cairo, Egypt | R18: Bancos
A19: =IF(B19="","",ROW()-2) | B19: GCF-MLD: Integrated Approach for Money Laundering Detection Using Machine Learning and Graph Network Analysis | C19: Irshad F.; Alkhalifah T.; Alturise F.; Khan Y.D. | D19: 2024 | E19: IEEE Access | F19: 10.1109/ACCESS.2024.3510115 | G19: Money laundering is a critical issue for financial institutions especially in developing countries and detecting such suspicious activities is a challenging task. The rule-based money laundering detection systems currently being used by the financial institutions rely on pre-defined rules that are often not able to keep up with rapidly changing tactics of money launderers. In this regard, machine learning based approaches have gained attention for detecting suspicious transactions related to money laundering. In this study, we propose a novel approach "Graph-Clustering Fusion for Money Laundering Detection (GCF-MLD)"combining graph network analysis with clustering methodology to identify suspicious accounts in real-world banking dataset. The results exhibit that the proposed model can be effectively used by the financial institutions to replace current rule-based techniques to significantly improve the efficiency and effectiveness of money laundering detection systems. © 2013 IEEE. | H19: Scopus | I19: =IF(B19="","",IF(AND(F19<>"",SUMPRODUCT(--ISNUMBER(SEARCH(Preseleccionados!$A$2:$A$11,F19)))>0),"YA ESTÁ",IF(AND(F19<>"",COUNTIF($F$3:F19,F19)>1),"REPETIDO",""))) | J19: =IF(OR(B19="",I19<>""),"",IF(MOD(COUNTIFS($B$3:B19,"<>",$I$3:I19,""),2)=1,"Carlos","Joaquín")) | K19: Sigue | L19: Sigue | P19: =IF(J19="","",IF(K19="Sale","Descartado",IF(L19="Sale","Descartado",IF(OR(M19="Q3",M19="Q4",M19="No aparece"),"Descartado",IF(N19="Sale","Descartado",IF(O19="Sigue","APROBADO","En proceso")))))) | Q19: University of Management and Technology, School of Systems and Technology, Department of Computer Science, Lahore, 54770, Pakistan; Qassim University, College of Computer, Department of Computer Engineering, Buraydah, 52571, Saudi Arabia; Qassim University, College of Computer, Department of Cybersecurity, Buraydah, 52571, Saudi Arabia | R19: Bancos
A20: =IF(B20="","",ROW()-2) | B20: Scalable Semi-Supervised Graph Learning Techniques for Anti Money Laundering | C20: Karim M.R.; Hermsen F.; Chala S.A.; De Perthuis P.; Mandal A. | D20: 2024 | E20: IEEE Access | F20: 10.1109/ACCESS.2024.3383784 | G20: Money laundering is the process by which criminals move large sums of illicit money to hidden locations and integrate them as legal funds through existing financial services. The United Nations (UN) estimates that 2 to 5% of global GDP, which is approximately 0.8 to 2.0 trillion dollars, is laundered globally every year. Therefore, accurately identifying such globally alarming activities is crucial for enforcing anti-money laundering (AML) measures. Numerous techniques have been proposed to detect money laundering from transaction graphs of money transfers between bank accounts by analysing the structural and behavioural dynamics of their corresponding dense subgraphs. However, these techniques often do not consider that money laundering usually involves high-volume flows of funds through chains of bank accounts. Moreover, most AML approaches either result in lower detection accuracy or incur higher computational costs, making them less reliable and suitable for real financial systems. Consequently, only a fraction of money laundering activities can be detected and prevented. In this paper, we propose an efficient approach to AML by employing semi-supervised graph learning techniques on a large-scale financial transactional graph in both pipeline settings (i.e., graph embedding models are first trained to generate node embeddings that are combined with additional topological graph features to train binary classifiers) and end-to-end settings (i.e., node classification is performed by training SkipGCN, FastGCN, and EvolveGCN without requiring separate classifiers) to identify nodes involved in potential money laundering activities. We evaluate our approach on four datasets: AMLSim, Elliptic, IBM AML, and SynthAML, with a view to scalability and practicality for real financial systems. Further, we provide local (e.g., how money is laundered between nodes) and global (e.g., what factors contribute to money laundering) explanations of the predictions by highlighting the predominant factors in money laundering cases and elucidating the mechanisms of illicit fund transfers between nodes to enhance the interpretability and transparency of the AML models. Experimental results suggest that our approach is scalable and effective at detecting money laundering from real and synthetic transaction graphs. © 2013 IEEE. | H20: Scopus | I20: =IF(B20="","",IF(AND(F20<>"",SUMPRODUCT(--ISNUMBER(SEARCH(Preseleccionados!$A$2:$A$11,F20)))>0),"YA ESTÁ",IF(AND(F20<>"",COUNTIF($F$3:F20,F20)>1),"REPETIDO",""))) | J20: =IF(OR(B20="",I20<>""),"",IF(MOD(COUNTIFS($B$3:B20,"<>",$I$3:I20,""),2)=1,"Carlos","Joaquín")) | P20: =IF(J20="","",IF(K20="Sale","Descartado",IF(L20="Sale","Descartado",IF(OR(M20="Q3",M20="Q4",M20="No aparece"),"Descartado",IF(N20="Sale","Descartado",IF(O20="Sigue","APROBADO","En proceso")))))) | Q20: Rwth Aachen University, Department of Information Systems and Databases, Aachen, 52074, Germany; Fraunhofer Fit, Department of Data Science and Artificial Intelligence, Sankt Augustin, 53757, Germany; École Normale Supérieure (ENS), Paris, 75005, France; Cosmian, Paris, 75008, France | R20: Bancos
A21: =IF(B21="","",ROW()-2) | B21: Incorporating machine learning and a risk-based strategy in an anti-money laundering multiagent system | C21: Alexandre C.R.; Balsa J. | D21: 2023 | E21: Expert Systems with Applications | F21: 10.1016/j.eswa.2023.119500 | G21: Over the last decade, the international community has become more aware of the danger and harm caused by the practice of the crime of Money Laundering (ML). Organizations to combat this crime were created and the existing laws were expanded and tightened. Complex legislation, combined with the increase in the volume of financial transactions involved in money laundering schemes, motivated research targeting the improvement and automation of the critical processes of detecting, signaling and communicating suspicious clients. The Anti-Money Laundering (AML) activity is strongly impacted and dependent on this process, which has evolved slowly, in part due to its subjectivity and complexity. This article presents the characteristics of a multiagent system that incorporates machine learning and risk components to identify and flag suspicious bank clients. It also seeks to help human specialists in the analysis of suspicious behavior by these clients. The knowledge bases are obtained through data mining over a real database, obtaining for each client a transactional behavior pattern, enriched with specific rules based on legal aspects, and on the expertise of the AML analysts of the financial institution that funds this research. The adopted risk strategy seeks to identify and classify the ML risk level of each flagged client. To evaluate its results, the system analyzed six months of actual transactions. A set of candidate clients was produced and subsequently investigated by the financial institution's AML analysts, who proved a high degree of correctness in the indicated suspicions, including cases that were not flagged by the antecedent systems in execution for decades at the institution. © 2023 | H21: Scopus | I21: =IF(B21="","",IF(AND(F21<>"",SUMPRODUCT(--ISNUMBER(SEARCH(Preseleccionados!$A$2:$A$11,F21)))>0),"YA ESTÁ",IF(AND(F21<>"",COUNTIF($F$3:F21,F21)>1),"REPETIDO",""))) | J21: =IF(OR(B21="",I21<>""),"",IF(MOD(COUNTIFS($B$3:B21,"<>",$I$3:I21,""),2)=1,"Carlos","Joaquín")) | K21: Sigue | L21: Sigue | P21: =IF(J21="","",IF(K21="Sale","Descartado",IF(L21="Sale","Descartado",IF(OR(M21="Q3",M21="Q4",M21="No aparece"),"Descartado",IF(N21="Sale","Descartado",IF(O21="Sigue","APROBADO","En proceso")))))) | Q21: LASIGE, Faculdade de Ciências da Universidade de Lisboa, Edifício C6, Campo Grande, Lisboa, 1749-016, Portugal | R21: Bancos
A22: =IF(B22="","",ROW()-2) | B22: Finding money launderers using heterogeneous graph neural networks | C22: Johannessen F.; Jullum M. | D22: 2025 | E22: Journal of Finance and Data Science | F22: 10.1016/j.jfds.2025.100175 | G22: The finance industry depends on effective anti-money laundering (AML) systems to ensure compliance and maintain operational efficiency. However, existing AML systems, which are predominantly rule-based, frequently struggle to detect money laundering accurately. In particular, their inability to learn from historical data and properly account for diverse customer behavior is problematic. Also accounting for the vast amounts of transactional data generated daily, this challenge calls for big data analytics and advanced machine learning techniques. In line with this, the present paper explores a graph neural network (GNN) approach, a state-of-the-art machine learning technique, to identify money laundering activities within a large heterogeneous network constructed from real-world bank transactions and business role data from DNB, Norway’s largest bank. To this end, we extend the (homogeneous) Message Passing Neural Network (MPNN) architecture to operate on a heterogeneous graph, and demonstrate its strong performance in detecting money laundering activities. We showcase the suitability of utilizing GNN methodology to improve electronic surveillance systems for detecting money laundering, thereby contributing a pioneering approach to AML through the application of advanced data science techniques. To the best of our knowledge, this is the first publication applying heterogeneous GNNs for AML purposes with a large real-world heterogeneous network. Copyright © 2025. Publishing services by Elsevier B.V. | H22: Scopus | I22: =IF(B22="","",IF(AND(F22<>"",SUMPRODUCT(--ISNUMBER(SEARCH(Preseleccionados!$A$2:$A$11,F22)))>0),"YA ESTÁ",IF(AND(F22<>"",COUNTIF($F$3:F22,F22)>1),"REPETIDO",""))) | J22: =IF(OR(B22="",I22<>""),"",IF(MOD(COUNTIFS($B$3:B22,"<>",$I$3:I22,""),2)=1,"Carlos","Joaquín")) | P22: =IF(J22="","",IF(K22="Sale","Descartado",IF(L22="Sale","Descartado",IF(OR(M22="Q3",M22="Q4",M22="No aparece"),"Descartado",IF(N22="Sale","Descartado",IF(O22="Sigue","APROBADO","En proceso")))))) | Q22: DNB, P.O. Box 1600, Sentrum, Oslo, NO-0021, Norway; Norwegian Computing Center, P.O. Box 114, Blindern, Oslo, NO-0314, Norway | R22: Bancos
A23: =IF(B23="","",ROW()-2) | B23: Unveiling sentiments of the cullen commission: Exploring AML compliance and regulation through deep learning techniques | C23: Lokanan M.E. | D23: 2025 | E23: Journal of Economic Criminology | F23: 10.1016/j.jeconc.2025.100138 | G23: This paper examines the role of anti-money laundering (AML) regulations and compliance in combating money laundering and terrorist financing (ML/TF) in Canada. AML regulations establish guidelines for financial institutions to identify, prevent, and report suspicious activities. However, tensions often arise between AML compliance and regulation due to the challenges associated with implementing and adhering to AML regulations. This paper aims to investigate the sentiments expressed by individuals involved in AML compliance and regulation regarding the effectiveness of AML measures in the Canadian financial sector. The paper uses advanced deep learning (DL) methods like convolutional neural networks (CNN), recurrent neural networks with long short-term memory (RNN+LSTM), and pre-trained models like GloVe and BERT to explore emotions in the context of AML compliance and regulation. The findings indicate that DL models excel at accurately classifying sentiments from testimonies related to AML compliance and regulation. However, there are challenges in accurately capturing negative sentiments, which reflect the complexities and nuances associated with expressing criticisms about regulatory standards. The study emphasizes the importance of understanding the interplay between rational decision-making in compliance and the inherent conflicts with regulation. This article also highlights how DL models can potentially enhance sentiment analysis in the AML enterprise, enabling analysts to make decisions and policies based on financial intelligence. Nevertheless, DL models are not always easy to comprehend. Further research is needed to enhance the understandability and scalability of DL models when analyzing different AML datasets. © 2025 | H23: Scopus | I23: =IF(B23="","",IF(AND(F23<>"",SUMPRODUCT(--ISNUMBER(SEARCH(Preseleccionados!$A$2:$A$11,F23)))>0),"YA ESTÁ",IF(AND(F23<>"",COUNTIF($F$3:F23,F23)>1),"REPETIDO",""))) | J23: =IF(OR(B23="",I23<>""),"",IF(MOD(COUNTIFS($B$3:B23,"<>",$I$3:I23,""),2)=1,"Carlos","Joaquín")) | K23: Sale | P23: =IF(J23="","",IF(K23="Sale","Descartado",IF(L23="Sale","Descartado",IF(OR(M23="Q3",M23="Q4",M23="No aparece"),"Descartado",IF(N23="Sale","Descartado",IF(O23="Sigue","APROBADO","En proceso")))))) | Q23: Faculty of Management. Royal Roads University, 2005 Sooke Road, royalroads.ca, Victoria, V9B 5Y2, BC, Canada | R23: Bancos
A24: =IF(B24="","",ROW()-2) | B24: Are the old ways of transaction monitoring dead? | C24: Gilson C. | D24: 2024 | E24: Journal of Financial Compliance | F24: 10.69554/RJCX4578 | G24: Financial institutions continue to face the challenge of demonstrating a comprehensive anti-money laundering (AML) transaction monitoring programme that is designed to detect, and aligns with, relevant Federal Financial Institutions Examinations Council (FFIEC) red flags without explicit, consistent confirmation on whether the escalations (ie Suspicious Activity Report [SAR] filings) are correct or valuable. Historically, this led most banks to adopt the use of typology-based if/then rules, resulting in a significant volume of alerts to be reviewed and dispositioned, with only a small portion being identified as potentially suspicious. While machine learning models are touted as an obvious fix to this problem, many banks may find such solutions to be far too expensive, complex and/or resource intensive. In order to answer the question, ‘are the old ways of transaction monitoring dead?’, this paper offers and evaluates various practical solutions, ranging from simple to sophisticated, to reduce false positive alerts generated by traditional AML transaction monitoring applications. © 2024, Henry Stewart Publications. All rights reserved. | H24: Scopus | I24: =IF(B24="","",IF(AND(F24<>"",SUMPRODUCT(--ISNUMBER(SEARCH(Preseleccionados!$A$2:$A$11,F24)))>0),"YA ESTÁ",IF(AND(F24<>"",COUNTIF($F$3:F24,F24)>1),"REPETIDO",""))) | J24: =IF(OR(B24="",I24<>""),"",IF(MOD(COUNTIFS($B$3:B24,"<>",$I$3:I24,""),2)=1,"Carlos","Joaquín")) | P24: =IF(J24="","",IF(K24="Sale","Descartado",IF(L24="Sale","Descartado",IF(OR(M24="Q3",M24="Q4",M24="No aparece"),"Descartado",IF(N24="Sale","Descartado",IF(O24="Sigue","APROBADO","En proceso")))))) | Q24: U.S. Bank, United States; U.S. Bank, 190 S. LaSalle Ave., Chicago, 60603, IL, United States | R24: Bancos
